<?xml version="1.0"?>
<robot name="fms_robot" xmlns:xacro="http://www.ros.org/wiki/xacro">

  <xacro:arg name="robot_name" default="robot_1"/>

  <!-- Dimensions (from mobile_base.xacro reference design) -->
  <xacro:property name="base_length"   value="0.6"/>
  <xacro:property name="base_width"    value="0.4"/>
  <xacro:property name="base_height"   value="0.2"/>
  <xacro:property name="wheel_radius"  value="0.1"/>
  <xacro:property name="wheel_length"  value="0.05"/>
  <xacro:property name="caster_radius" value="0.05"/>

  <!-- Inertia helpers -->
  <xacro:macro name="box_inertia" params="m x y z">
    <inertial>
      <mass value="${m}"/>
      <inertia ixx="${m*(y*y+z*z)/12}" ixy="0" ixz="0"
               iyy="${m*(x*x+z*z)/12}" iyz="0"
               izz="${m*(x*x+y*y)/12}"/>
    </inertial>
  </xacro:macro>

  <xacro:macro name="cylinder_inertia" params="m r h">
    <inertial>
      <mass value="${m}"/>
      <inertia ixx="${m*(3*r*r+h*h)/12}" ixy="0" ixz="0"
               iyy="${m*(3*r*r+h*h)/12}" iyz="0"
               izz="${m*r*r/2}"/>
    </inertial>
  </xacro:macro>

  <xacro:macro name="sphere_inertia" params="m r">
    <inertial>
      <mass value="${m}"/>
      <inertia ixx="${2*m*r*r/5}" ixy="0" ixz="0"
               iyy="${2*m*r*r/5}" iyz="0"
               izz="${2*m*r*r/5}"/>
    </inertial>
  </xacro:macro>

  <!-- ===== LINKS — plain names, no robot_name prefix =====
       RSP runs with frame_prefix:=robot_N/ so TF frames are robot_N/base_link etc.
       RViz RobotModel sets TF Prefix = robot_N to match.
       Gazebo sensors attach correctly because link names have no slashes. -->

  <link name="base_footprint">
    <xacro:sphere_inertia m="0.0001" r="0.0001"/>
  </link>

  <joint name="base_joint" type="fixed">
    <parent link="base_footprint"/>
    <child  link="base_link"/>
    <origin xyz="0 0 ${wheel_radius}" rpy="0 0 0"/>
  </joint>

  <gazebo reference="base_joint">
    <preserveFixedJoint>true</preserveFixedJoint>
  </gazebo>

  <!-- ===== BASE LINK ===== -->
  <link name="base_link">
    <visual>
      <geometry>
        <box size="${base_length} ${base_width} ${base_height}"/>
      </geometry>
      <origin xyz="0 0 ${base_height/2.0}" rpy="0 0 0"/>
      <material name="blue"><color rgba="0.1 0.4 0.8 1.0"/></material>
    </visual>
    <collision>
      <geometry>
        <box size="${base_length} ${base_width} ${base_height}"/>
      </geometry>
      <origin xyz="0 0 ${base_height/2.0}" rpy="0 0 0"/>
    </collision>
    <xacro:box_inertia m="5.0" x="${base_length}" y="${base_width}" z="${base_height}"/>
  </link>

  <!-- ===== WHEELS ===== -->
  <xacro:macro name="wheel_link" params="prefix">
    <link name="${prefix}_link">
      <visual>
        <geometry>
          <cylinder radius="${wheel_radius}" length="${wheel_length}"/>
        </geometry>
        <origin xyz="0 0 0" rpy="0 0 0"/>
        <material name="grey"><color rgba="0.4 0.4 0.4 1.0"/></material>
      </visual>
      <collision>
        <geometry><sphere radius="${wheel_radius}"/></geometry>
        <origin xyz="0 0 0" rpy="0 0 0"/>
      </collision>
      <xacro:cylinder_inertia m="1.0" r="${wheel_radius}" h="${wheel_length}"/>
    </link>
  </xacro:macro>

  <xacro:wheel_link prefix="right_wheel"/>
  <xacro:wheel_link prefix="left_wheel"/>

  <joint name="base_right_wheel_joint" type="continuous">
    <parent link="base_link"/>
    <child  link="right_wheel_link"/>
    <origin xyz="${-base_length/4.0} ${-(base_width+wheel_length)/2.0} 0"
            rpy="${pi/2.0} 0 0"/>
    <axis xyz="0 0 -1"/>
    <dynamics damping="0.1" friction="0.1"/>
  </joint>

  <joint name="base_left_wheel_joint" type="continuous">
    <parent link="base_link"/>
    <child  link="left_wheel_link"/>
    <origin xyz="${-base_length/4.0} ${(base_width+wheel_length)/2.0} 0"
            rpy="${pi/2.0} 0 0"/>
    <axis xyz="0 0 -1"/>
    <dynamics damping="0.1" friction="0.1"/>
  </joint>

  <!-- ===== CASTER ===== -->
  <link name="caster_wheel_link">
    <visual>
      <geometry><sphere radius="${caster_radius}"/></geometry>
      <material name="grey"><color rgba="0.5 0.5 0.5 1.0"/></material>
    </visual>
    <collision>
      <geometry><sphere radius="${caster_radius}"/></geometry>
    </collision>
    <xacro:sphere_inertia m="0.5" r="${caster_radius}"/>
  </link>

  <joint name="base_caster_wheel_joint" type="fixed">
    <parent link="base_link"/>
    <child  link="caster_wheel_link"/>
    <origin xyz="${base_length/3.0} 0 ${-wheel_radius/2.0}" rpy="0 0 0"/>
  </joint>

  <!-- ===== LIDAR ===== -->
  <link name="lidar_link">
    <visual>
      <geometry><cylinder radius="0.04" length="0.06"/></geometry>
      <material name="blue_bright"><color rgba="0.0 0.5 1.0 1.0"/></material>
    </visual>
    <collision>
      <geometry><cylinder radius="0.04" length="0.06"/></geometry>
    </collision>
    <inertial>
      <mass value="0.2"/>
      <inertia ixx="0.0001" ixy="0" ixz="0" iyy="0.0001" iyz="0" izz="0.0001"/>
    </inertial>
  </link>

  <joint name="lidar_joint" type="fixed">
    <parent link="base_link"/>
    <child  link="lidar_link"/>
    <origin xyz="0 0 ${base_height + 0.03}" rpy="0 0 0"/>
  </joint>

  <!-- ===== IMU ===== -->
  <link name="imu_link">
    <visual>
      <geometry><box size="0.03 0.03 0.01"/></geometry>
      <material name="green"><color rgba="0.0 0.8 0.0 1.0"/></material>
    </visual>
    <inertial>
      <mass value="0.01"/>
      <inertia ixx="0.000001" ixy="0" ixz="0" iyy="0.000001" iyz="0" izz="0.000001"/>
    </inertial>
  </link>

  <joint name="imu_joint" type="fixed">
    <parent link="base_link"/>
    <child  link="imu_link"/>
    <origin xyz="0 0 0" rpy="0 0 0"/>
  </joint>

  <!-- ===== GAZEBO physics ===== -->
  <gazebo reference="caster_wheel_link">
    <mu1>0.1</mu1><mu2>0.1</mu2>
  </gazebo>
  <gazebo reference="left_wheel_link">
    <mu1>1.0</mu1><mu2>1.0</mu2><kp>1000000.0</kp><kd>100.0</kd><minDepth>0.001</minDepth>
  </gazebo>
  <gazebo reference="right_wheel_link">
    <mu1>1.0</mu1><mu2>1.0</mu2><kp>1000000.0</kp><kd>100.0</kd><minDepth>0.001</minDepth>
  </gazebo>

  <!-- ===== GAZEBO: Differential Drive =====
       frame_id / child_frame_id are TF *string names*, not link names.
       They are namespaced with robot_name so each robot's odom TF is unique.
       Joint references use the plain URDF joint names. -->
  <gazebo>
    <plugin filename="gz-sim-diff-drive-system"
            name="gz::sim::systems::DiffDrive">
      <left_joint>base_left_wheel_joint</left_joint>
      <right_joint>base_right_wheel_joint</right_joint>
      <wheel_separation>${base_width + wheel_length}</wheel_separation>
      <wheel_radius>${wheel_radius}</wheel_radius>
      <odom_publish_frequency>20</odom_publish_frequency>
      <topic>/$(arg robot_name)/cmd_vel</topic>
      <odom_topic>/$(arg robot_name)/odom</odom_topic>
      <tf_topic>/$(arg robot_name)/tf</tf_topic>
      <frame_id>$(arg robot_name)/odom</frame_id>
      <child_frame_id>$(arg robot_name)/base_footprint</child_frame_id>
      <min_velocity>-1.0</min_velocity>
      <max_velocity>1.0</max_velocity>
      <min_acceleration>-3.0</min_acceleration>
      <max_acceleration>3.0</max_acceleration>
    </plugin>
  </gazebo>

  <!-- ===== GAZEBO: Joint State Publisher ===== -->
  <gazebo>
    <plugin filename="gz-sim-joint-state-publisher-system"
            name="gz::sim::systems::JointStatePublisher">
      <topic>/$(arg robot_name)/joint_states</topic>
      <joint_name>base_left_wheel_joint</joint_name>
      <joint_name>base_right_wheel_joint</joint_name>
    </plugin>
  </gazebo>

  <!-- ===== GAZEBO: 2D Lidar =====
       reference="lidar_link" — plain name, no slash — Gazebo finds it correctly. -->
  <gazebo reference="lidar_link">
    <sensor name="lidar" type="gpu_lidar">
      <pose>0 0 0 0 0 0</pose>
      <topic>/$(arg robot_name)/scan</topic>
      <update_rate>10</update_rate>
      <lidar>
        <scan>
          <horizontal>
            <samples>360</samples>
            <resolution>1</resolution>
            <min_angle>-3.14159</min_angle>
            <max_angle>3.14159</max_angle>
          </horizontal>
        </scan>
        <range>
          <min>0.12</min>
          <max>12.0</max>
          <resolution>0.01</resolution>
        </range>
        <noise>
          <type>gaussian</type><mean>0.0</mean><stddev>0.01</stddev>
        </noise>
      </lidar>
      <always_on>true</always_on>
      <visualize>false</visualize>
    </sensor>
  </gazebo>

  <!-- ===== GAZEBO: IMU ===== -->
  <gazebo reference="imu_link">
    <sensor name="imu" type="imu">
      <topic>/$(arg robot_name)/imu</topic>
      <update_rate>100</update_rate>
      <always_on>true</always_on>
      <imu>
        <angular_velocity>
          <x><noise type="gaussian"><mean>0.0</mean><stddev>0.002</stddev></noise></x>
          <y><noise type="gaussian"><mean>0.0</mean><stddev>0.002</stddev></noise></y>
          <z><noise type="gaussian"><mean>0.0</mean><stddev>0.002</stddev></noise></z>
        </angular_velocity>
        <linear_acceleration>
          <x><noise type="gaussian"><mean>0.0</mean><stddev>0.017</stddev></noise></x>
          <y><noise type="gaussian"><mean>0.0</mean><stddev>0.017</stddev></noise></y>
          <z><noise type="gaussian"><mean>0.0</mean><stddev>0.017</stddev></noise></z>
        </linear_acceleration>
      </imu>
    </sensor>
  </gazebo>

</robot>
